DEVICE: cuda
file exists
file exists
file exists
file exists
file exists
file exists
file exists
file exists
file exists
file exists
file exists
no file
tests/processed_data/sparse_mini/Believe_7.p
tests/processed_data/sparse_mini/All the Things You Are_2.p
tests/processed_data/sparse_mini/Believe_9.p
tests/processed_data/sparse_mini/Believe_1.p
tests/processed_data/sparse_mini/All the Things You Are_4.p
tests/processed_data/sparse_mini/Believe_6.p
tests/processed_data/sparse_mini/Barbara Ann_4.p
tests/processed_data/sparse_mini/All the Things You Are_7.p
tests/processed_data/sparse_mini/All the Things You Are_1.p
tests/processed_data/sparse_mini/Believe_3.p
CONSTRUCTING THETA: torch.Size([36, 128]) torch.Size([36, 128])
Traceback (most recent call last):
  File "dp_test.py", line 29, in <module>
    train_vqvae.train(dataDir, outDir, modelDir, fstub=fstub, loss='dyn', batchsize=batchsize, batchlength=batchlength, normalize=True, quantize=True, sparse=sparse, num_embeddings=1024, embedding_dim=36)
  File "/projectnb2/textconv/sadiela/midi_generation/scripts/train_vqvae.py", line 52, in train
    recon_error, perplex, nan_recon_files = train_model(datapath, model, model_file, lossfunc=loss, bs=batchsize, batchlength=batchlength, normalize=normalize, quantize=quantize, sparse=sparse)
  File "/projectnb2/textconv/sadiela/midi_generation/scripts/vq_vae.py", line 314, in train_model
    recon_error = dynamic_loss(data_recon, data) #X_hat, then X!!!
  File "/projectnb2/textconv/sadiela/midi_generation/scripts/dp_loss.py", line 137, in forward
    theta, grad_theta_xhat = construct_theta(X[i][0], X_hat[i][0])
  File "/projectnb2/textconv/sadiela/midi_generation/scripts/dp_loss.py", line 40, in construct_theta
    grad_theta = torch.zeros((m*n, m*n, x_hat.shape[0], x_hat.shape[1]))
RuntimeError: [enforce fail at CPUAllocator.cpp:68] . DefaultCPUAllocator: can't allocate memory: you tried to allocate 5104242542592 bytes. Error code 12 (Cannot allocate memory)
python3: can't open file 'test_vqvae.py': [Errno 2] No such file or directory
START
no file
Traceback (most recent call last):
  File "train_vqvae.py", line 102, in <module>
    logging.basicConfig(filename=logfile, encoding='utf-8', level=numeric_level)
  File "/projectnb/textconv/sadiela/.conda/envs/py3/lib/python3.8/logging/__init__.py", line 2009, in basicConfig
    raise ValueError('Unrecognised argument(s): %s' % keys)
ValueError: Unrecognised argument(s): encoding
